## In java can we write a finally block without try catch block?

Yes, in Java, you can write a `finally` block without a `try`-`catch` block. The `finally` block is used to define code that should be executed regardless of whether an exception is thrown or not. It's often used for cleanup tasks like releasing resources (closing files, database connections, etc.) or ensuring that certain actions are taken regardless of the outcome of the code within the `try` block.

Here's an example where a `finally` block is used without a `try`-`catch` block:

```java
public class FinallyExample {
    public static void main(String[] args) {
        try {
            // Code that might or might not throw an exception
            int result = divide(10, 2);
            System.out.println("Result: " + result);
        } finally {
            System.out.println("This will be executed regardless.");
        }
    }

    public static int divide(int a, int b) {
        return a / b;
    }
}
```

In this example, the `finally` block will be executed no matter what, even if an exception is thrown inside the `try` block. The `divide` method will not throw an exception here, but if it did, the `finally` block would still execute.

So, while it's common to see `finally` blocks used in conjunction with `try`-`catch` blocks for exception handling, you can also use a `finally` block by itself for scenarios where you want certain code to be executed regardless of exceptions.

## Can we write try catch block inside finally block in java?

Yes, you can write a `try`-`catch` block inside a `finally` block in Java. However, it's quite unusual and often not recommended to do so.

The `finally` block is designed to execute code that should run regardless of whether an exception is thrown or not. Placing a `try`-`catch` block inside a `finally` block can lead to confusing and hard-to-maintain code.

Here's an example of how you might use a `try`-`catch` block inside a `finally` block:

```java
public class TryCatchInsideFinally {
    public static void main(String[] args) {
        try {
            System.out.println("Inside try block.");
            int result = divide(10, 0);
            System.out.println("Result: " + result);
        } finally {
            try {
                System.out.println("Inside finally's try block.");
                int value = 5 / 0;
                System.out.println("Value: " + value);
            } catch (Exception e) {
                System.out.println("Caught an exception in finally: " + e);
            }
        }
    }

    public static int divide(int a, int b) {
        return a / b;
    }
}
```

In this example, the `finally` block contains its own `try`-`catch` block. It's catching an exception within the `finally` block itself. However, this is not a recommended practice because it can make the code difficult to understand and maintain.

In most situations, it's better to use a `finally` block solely for cleanup tasks and not for handling exceptions. If you need to handle exceptions that occur within a `finally` block, it's often better to let them propagate up the call stack and handle them at a higher level where the context is clearer.

## can we write try finally in side catch block in java ?

Yes, you can write a `try`-`finally` block inside a `catch` block in Java. This can be useful when you want to ensure that certain cleanup or resource release tasks are performed regardless of whether an exception is caught in the `catch` block.

Here's an example of how you might use a `try`-`finally` block inside a `catch` block:

```java
public class TryFinallyInsideCatch {
    public static void main(String[] args) {
        try {
            int result = divide(10, 0);
            System.out.println("Result: " + result);
        } catch (ArithmeticException e) {
            System.out.println("Caught an ArithmeticException: " + e);

            try {
                System.out.println("Inside catch's try block.");
                int value = 5 / 0;
                System.out.println("Value: " + value);
            } finally {
                System.out.println("Inside catch's finally block.");
            }
        }
    }

    public static int divide(int a, int b) {
        return a / b;
    }
}
```

In this example, the outer `try` block catches an `ArithmeticException` when trying to divide by zero. Inside the `catch` block, there is a nested `try`-`finally` block. The `try` block inside the `catch` block performs another division by zero, which will result in an exception. The `finally` block within the nested `try` block will still be executed regardless of whether an exception is thrown.

While using a `try`-`finally` block inside a `catch` block is technically possible, it's important to use it judiciously to avoid overly complex code that becomes hard to understand. It's generally a good practice to separate error handling and cleanup logic to maintain code clarity.
